// [1] Event loop



// example 1
const timeout = setTimeout(()=>{
    console.log('Timeout')
}, 1500)

clearTimeout(timeout)                   //очищает 


// example 2
const interval = setInterval( () =>{
    console.log('interval 1sec')
}, 1000)                               // будет выводить в консоль каждую секунду сообщение 

clearInterval(interval)

// example 3
const delay = (callback, wait = 1000) => {
    setTimeout(callback, wait)
}

delay( ()=> {
    console.log('after 2 sec')
}, 2000)



// [2] Promise 


// example 1
// let promise = new Promise( function(resolve, reject) {
//     return resolve('DONE!')
// })
// console.log(promise)                                        // Promise { 'DONE!' }

// // example 2
// let promise2 = new Promise( (resolve, reject)=> 
//     reject(new Error('...have problems :( ')), 1000
// )                                   
// console.log(promise2)                                       // Error: ...have problems :(

// // example 3
// let promise3 = new Promise( (resolve, reeject) => 
//     resolve(123)                                            //мгновенно выдаст результат: 123
// )
// console.log(promise3)                                       // Promise { 123 }


// Method then 
// promise.then(
//     function(result) { /* обработает успешное выполнение */ },
//     function(error) { /* обработает ошибку */ }
// )

// example successful promise 
// let promise = new Promise((resolve, reject) => {
//     return setTimeout( ()=> resolve('Done!!!'), 1000)
// })
// promise.then( 
//     function(result) { return console.log(result)},
//     function(error) { return console.log(error)}
// )                                       // Done!!!
// // example error 
// let promise = new Promise((resolve,reject) => {
//     return setTimeout( () => reject(new Error('ops, have problem...')))
// })
// promise.then(
//     result => console.log(result),
//     error => console.log(error)
// )                                                            // Error: ops, have problem...


// Method catch (если нам нужно обработать только ошибку, то лучше использовать catch)
// const promise = new Promise ( (resolve, reject)=> {
//     return setTimeout( () => reject(new Error('Ошибка!')), 2000)
// })
// promise.catch(console.log())                                 // UnhandledPromiseRejectionWarning: Error: Ошибка!


// Method finally 
// похож на .then, потому что тоже выполняет обе функции
// finally не имеет аргументов и пропускает результат к следующим обработчикам
// let promise = new Promise((resolve, reject) => {
//     return setTimeout( () => resolve('result'), 2000)
// }) 
// promise.finally( () => console.log('Promise end'))           // Promise end
// .then( result => console.log(result))                        // result

// let promise2 = new Promise((resolve, reject)=> {
//     return setTimeout( () => reject(new Error('Ошибка...')))
// })
// promise2.finally(() => console.log('Промис завершился'))     // Промис завершился
// .catch(error => console.log(error))                              // Error: Ошибка...



// [2] async  

// function async always return Promise 
// async function f() {
//     return 23
// }
// console.log(f())                     // Promise { 23 }

// // тут видно, что нет разницы, можно вернуть промис, но результат будет одинаковым
// async function f2() {
//     return Promise.resolve(23)
// }
// console.log(f())                     // Promise { 23 }
// // example 3
// async function f3() {
//     return 'Hello, guys!'
// }
// f3().then(console.log(f3()))         // Promise { 'Hello, guys!' }


// [3] Await

// work only in async function 
// await заставляет ждать до тех пор пока промис справа от await не выполнится 
// const value = await promise 

// async function f( ) { 
// const promise = new Promise((resolve, reject) => {
//     return setTimeout( () => resolve('готово!'), 2500)
// })
// let results = await promise          // будет ждать пока промис не выполнится 
// console.log(results);
// }

// f();











// example 3
const delay = (wait = 1000) => {
    const promise = new Promise ( (resolve, reject) => {
        setTimeout( () => {
            // resolve()
            reject('Error :(')
        }, wait)
    })
    return promise
}
delay()                                   // (node:8256) UnhandledPromiseRejectionWarning: Error :(

// // example 4
// // delay(2500)
// //     .then(()=>{
// //         console.log('after 2 seconds')
// //     })
// //     .catch(err => console.error('Error', err))
// //     .finally( () => console.log('Finally'))
    
// //
// const getData = () => new Promise( resolve => resolve([
//     1, 1, 2, 3, 5, 8, 13
// ]))

// // getData().then(data => console.log(data))

// async function asyncExample() {
//     try {
//         await delay(3000)
//         const data = await getData()
//         console.log('data', data)
//     } catch (e) {
//         console.log(e)
//     } finally {
//         console.log('Finally')
//     }
// }